<?xml version="1.0" ?>
<!-- =================================================================================== -->
<!-- |    This document was autogenerated by xacro from d03x_kinema.xacro              | -->
<!-- |    EDITING THIS FILE BY HAND IS NOT RECOMMENDED                                 | -->
<!-- =================================================================================== -->
<robot name="d03x">
  <material name="white">
    <color rgba="1.0 1.0 1.0 1.0"/>
  </material>
  <material name="silver">
    <color rgba="0.8 0.8 0.8 1.0"/>
  </material>
  <material name="dark">
    <color rgba="0.3 0.3 0.3 1.0"/>
  </material>
  <material name="gray">
    <color rgba="0.2 0.2 0.2 1.0"/>
  </material>
  <material name="black">
    <color rgba="0.0 0.0 0.0 1.0"/>
  </material>
  <material name="red">
    <color rgba="0.8 0.0 0.0 1.0"/>
  </material>
  <material name="green">
    <color rgba="0.0 0.8 0.0 1.0"/>
  </material>
  <material name="blue">
    <color rgba="0.0 0.0 0.8 1.0"/>
  </material>
  <material name="orange">
    <color rgba="1.0 0.4235294117647059 0.0392156862745098 1.0"/>
  </material>
  <material name="brown">
    <color rgba="0.8705882352941177 0.8117647058823529 0.7647058823529411 1.0"/>
  </material>
  <link name="base_footprint"/>
  <joint name="base_joint" type="fixed">
    <parent link="base_footprint"/>
    <child link="base_link"/>
    <origin rpy="0 0 0" xyz="0 0 0"/>
  </joint>
  <link name="base_link">
    <visual>
      <origin rpy="0 0 0" xyz="0 0 0"/>
      <geometry>
        <mesh filename="package://d03_description/meshes/base.stl" scale="0.001 0.001 0.001"/>
      </geometry>
      <material name="alminium"/>
    </visual>
    <collision>
      <origin rpy="0 0 0" xyz="0 0 0"/>
      <geometry>
        <mesh filename="package://d03_description/meshes/base.stl" scale="0.001 0.001 0.001"/>
      </geometry>
    </collision>
  </link>
  <joint name="wheel_left_joint" type="continuous">
    <parent link="base_link"/>
    <child link="left_wheel_link"/>
    <origin rpy="1.570796 0 0" xyz="0.129 0.153 0.101"/>
    <limit effort="1.0" velocity="1.0"/>
    <axis rpy="0 0 0" xyz="0 0 1"/>
  </joint>
  <link name="left_wheel_link">
    <visual>
      <origin rpy="0 0 0" xyz="0 0 0"/>
      <geometry>
        <mesh filename="package://d03_description/meshes/wheel_and_hub.stl" scale="0.001 0.001 0.001"/>
      </geometry>
      <material name="dark"/>
    </visual>
    <collision>
      <origin rpy="0 0 0" xyz="0 0 0"/>
      <geometry>
        <mesh filename="package://d03_description/meshes/wheel_and_hub.stl" scale="0.001 0.001 0.001"/>
      </geometry>
    </collision>
  </link>
  <joint name="wheel_right_joint" type="continuous">
    <parent link="base_link"/>
    <child link="right_wheel_link"/>
    <origin rpy="-1.570796 0 0" xyz="0.129 -0.153 0.101"/>
    <limit effort="1.0" velocity="1.0"/>
    <axis rpy="0 0 0" xyz="0 0 1"/>
  </joint>
  <link name="right_wheel_link">
    <visual>
      <origin rpy="0 0 0" xyz="0 0 0"/>
      <geometry>
        <mesh filename="package://d03_description/meshes/wheel_and_hub.stl" scale="0.001 0.001 0.001"/>
      </geometry>
      <material name="dark"/>
    </visual>
    <collision>
      <origin rpy="0 0 0" xyz="0 0 0"/>
      <geometry>
        <mesh filename="package://d03_description/meshes/wheel_and_hub.stl" scale="0.001 0.001 0.001"/>
      </geometry>
    </collision>
  </link>
  <joint name="left_caster_housing_joint" type="continuous">
    <parent link="base_link"/>
    <child link="left_caster_housing_link"/>
    <origin rpy="0 0 3.1415926" xyz="-0.14 0.14 0.089837"/>
    <axis rpy="0 0 0" xyz="0 0 1"/>
  </joint>
  <link name="left_caster_housing_link">
    <visual>
      <origin rpy="0 0 0" xyz="0 0 0"/>
      <geometry>
        <mesh filename="package://d03_description/meshes/caster_housing.stl" scale="0.001 0.001 0.001"/>
      </geometry>
      <material name="dark"/>
    </visual>
    <collision>
      <origin rpy="0 0 0" xyz="0 0 0"/>
      <geometry>
        <mesh filename="package://d03_description/meshes/caster_housing.stl" scale="0.001 0.001 0.001"/>
      </geometry>
    </collision>
  </link>
  <joint name="left_caster_wheel_joint" type="continuous">
    <parent link="left_caster_housing_link"/>
    <child link="left_caster_wheel_link"/>
    <origin rpy="0 0 0" xyz="0.031 0.0 -0.052"/>
    <axis rpy="0 0 0" xyz="0 1 0"/>
  </joint>
  <link name="left_caster_wheel_link">
    <visual>
      <origin rpy="0 0 0" xyz="0 0 0"/>
      <geometry>
        <mesh filename="package://d03_description/meshes/caster_wheel.stl" scale="0.001 0.001 0.001"/>
      </geometry>
      <material name="dark"/>
    </visual>
    <collision>
      <origin rpy="0 0 0" xyz="0 0 0"/>
      <geometry>
        <mesh filename="package://d03_description/meshes/caster_wheel.stl" scale="0.001 0.001 0.001"/>
      </geometry>
    </collision>
  </link>
  <joint name="right_caster_housing_joint" type="continuous">
    <parent link="base_link"/>
    <child link="right_caster_housing_link"/>
    <origin rpy="0 0 3.1415926" xyz="-0.14 -0.14 0.089837"/>
    <axis rpy="0 0 0" xyz="0 0 1"/>
  </joint>
  <link name="right_caster_housing_link">
    <visual>
      <origin rpy="0 0 0" xyz="0 0 0"/>
      <geometry>
        <mesh filename="package://d03_description/meshes/caster_housing.stl" scale="0.001 0.001 0.001"/>
      </geometry>
      <material name="dark"/>
    </visual>
    <collision>
      <origin rpy="0 0 0" xyz="0 0 0"/>
      <geometry>
        <mesh filename="package://d03_description/meshes/caster_housing.stl" scale="0.001 0.001 0.001"/>
      </geometry>
    </collision>
  </link>
  <joint name="right_caster_wheel_joint" type="continuous">
    <parent link="right_caster_housing_link"/>
    <child link="right_caster_wheel_link"/>
    <origin rpy="0 0 0" xyz="0.031 0.0 -0.052"/>
    <axis rpy="0 0 0" xyz="0 1 0"/>
  </joint>
  <link name="right_caster_wheel_link">
    <visual>
      <origin rpy="0 0 0" xyz="0 0 0"/>
      <geometry>
        <mesh filename="package://d03_description/meshes/caster_wheel.stl" scale="0.001 0.001 0.001"/>
      </geometry>
      <material name="dark"/>
    </visual>
    <collision>
      <origin rpy="0 0 0" xyz="0 0 0"/>
      <geometry>
        <mesh filename="package://d03_description/meshes/caster_wheel.stl" scale="0.001 0.001 0.001"/>
      </geometry>
    </collision>
  </link>
</robot>

