<?xml version="1.0"?>
<robot name="d03x" xmlns:xacro="https://ros.org/wiki/xacro">

  <material name="dark">
    <color rgba="0.3 0.3 0.3 1.0"/>
  </material>

  <material name="alminium">
    <color rgba=".8 .8 .8 1"/>
  </material>

  <link name="base_footprint"/>

  <joint name="base_joint" type="fixed">
    <parent link="base_footprint"/>
    <child link="base_link"/>
    <origin xyz="0 0 0" rpy="0 0 0"/>
  </joint>

  <link name="base_link">
    <visual>
      <origin xyz="0 0 0" rpy="0 0 0"/>
      <geometry>
        <mesh filename="package://d03_description/meshes/base.stl" scale="0.001 0.001 0.001"/>
      </geometry>
      <material name="alminium"/>
    </visual>
    <collision>
      <origin xyz="0 0 0" rpy="0 0 0"/>
      <geometry>
        <mesh filename="package://d03_description/meshes/base.stl" scale="0.001 0.001 0.001"/>
      </geometry>
    </collision>
  </link>

  <joint name="wheel_left_joint" type="continuous">
    <parent link="base_link"/>
    <child link="left_wheel_link"/>
    <origin xyz="0.129 0.153 0.101" rpy="1.570796 0 0"/>
    <limit effort="1.0" velocity="1.0"/>
    <axis rpy="0 0 0" xyz="0 0 1"/>
  </joint>

  <link name="left_wheel_link">
    <visual>
      <origin xyz="0 0 0" rpy="0 0 0"/>
      <geometry>
        <mesh filename="package://d03_description/meshes/wheel_and_hub.stl" scale="0.001 0.001 0.001"/>
      </geometry>
      <material name="dark"/>
    </visual>
    <collision>
      <origin xyz="0 0 0" rpy="0 0 0"/>
      <geometry>
        <mesh filename="package://d03_description/meshes/wheel_and_hub.stl" scale="0.001 0.001 0.001"/>
      </geometry>
    </collision>
  </link>


  <joint name="wheel_right_joint" type="continuous">
    <parent link="base_link"/>
    <child link="right_wheel_link"/>
    <origin xyz="0.129 -0.153 0.101" rpy="-1.570796 0 0"/>
    <limit effort="1.0" velocity="1.0"/>
    <axis rpy="0 0 0" xyz="0 0 1"/>
  </joint>

  <link name="right_wheel_link">
    <visual>
      <origin xyz="0 0 0" rpy="0 0 0"/>
      <geometry>
        <mesh filename="package://d03_description/meshes/wheel_and_hub.stl" scale="0.001 0.001 0.001"/>
      </geometry>
      <material name="dark"/>
    </visual>
    <collision>
      <origin xyz="0 0 0" rpy="0 0 0"/>
      <geometry>
        <mesh filename="package://d03_description/meshes/wheel_and_hub.stl" scale="0.001 0.001 0.001"/>
      </geometry>
    </collision>
  </link>

  <!--left caster-->
  <joint name="caster_housing_left_joint" type="continuous">
    <parent link="base_link"/>
    <child link="caster_housing_left_link"/>
    <origin xyz="-0.14 0.14 0.089837" rpy="0 0 3.1415926"/>
    <!-- <limit effort="1.0" velocity="1.0"/> -->
    <axis rpy="0 0 0" xyz="0 0 1"/>
  </joint>

  <link name="caster_housing_left_link">
    <visual>
      <origin xyz="0 0 0" rpy="0 0 0"/>
      <geometry>
        <mesh filename="package://d03_description/meshes/caster_housing.stl" scale="0.001 0.001 0.001"/>
      </geometry>
      <material name="dark"/>
    </visual>
    <collision>
      <origin xyz="0 0 0" rpy="0 0 0"/>
      <geometry>
        <mesh filename="package://d03_description/meshes/caster_housing.stl" scale="0.001 0.001 0.001"/>
      </geometry>
    </collision>
  </link>

  <joint name="caster_wheel_left_joint" type="continuous">
    <parent link="caster_housing_left_link"/>
    <child link="caster_wheel_left_link"/>
    <origin xyz="0.031 0.0 -0.052" rpy="0 0 0"/>
    <!-- <limit effort="1.0" velocity="1.0"/> -->
    <axis rpy="0 0 0" xyz="0 1 0"/>
  </joint>

  <link name="caster_wheel_left_link">
    <visual>
      <origin xyz="0 0 0" rpy="0 0 0"/>
      <geometry>
        <mesh filename="package://d03_description/meshes/caster_wheel.stl" scale="0.001 0.001 0.001"/>
      </geometry>
      <material name="dark"/>
    </visual>
    <collision>
      <origin xyz="0 0 0" rpy="0 0 0"/>
      <geometry>
        <mesh filename="package://d03_description/meshes/caster_wheel.stl" scale="0.001 0.001 0.001"/>
      </geometry>
    </collision>
  </link>
  <!--right caster-->
  <joint name="caster_housing_right_joint" type="continuous">
    <parent link="base_link"/>
    <child link="caster_housing_right_link"/>
    <origin xyz="-0.14 -0.14 0.089837" rpy="0 0 3.1415926"/>
    <!-- <limit effort="1.0" velocity="1.0"/> -->
    <axis rpy="0 0 0" xyz="0 0 1"/>
  </joint>

  <link name="caster_housing_right_link">
    <visual>
      <origin xyz="0 0 0" rpy="0 0 0"/>
      <geometry>
        <mesh filename="package://d03_description/meshes/caster_housing.stl" scale="0.001 0.001 0.001"/>
      </geometry>
      <material name="dark"/>
    </visual>
    <collision>
      <origin xyz="0 0 0" rpy="0 0 0"/>
      <geometry>
        <mesh filename="package://d03_description/meshes/caster_housing.stl" scale="0.001 0.001 0.001"/>
      </geometry>
    </collision>
  </link>

  <joint name="caster_wheel_right_joint" type="continuous">
    <parent link="caster_housing_right_link"/>
    <child link="caster_wheel_right_link"/>
    <origin xyz="0.031 0.0 -0.052" rpy="0 0 0"/>
    <!-- <limit effort="1.0" velocity="1.0"/> -->
    <axis rpy="0 0 0" xyz="0 1 0"/>
  </joint>

  <link name="caster_wheel_right_link">
    <visual>
      <origin xyz="0 0 0" rpy="0 0 0"/>
      <geometry>
        <mesh filename="package://d03_description/meshes/caster_wheel.stl" scale="0.001 0.001 0.001"/>
      </geometry>
      <material name="dark"/>
    </visual>
    <collision>
      <origin xyz="0 0 0" rpy="0 0 0"/>
      <geometry>
        <mesh filename="package://d03_description/meshes/caster_wheel.stl" scale="0.001 0.001 0.001"/>
      </geometry>
    </collision>
  </link>
</robot>

